<?xml version="1.0" encoding="utf-8"?>
<!-- This URDF was automatically created by SolidWorks to URDF Exporter! Originally created by Stephen Brawner (brawner@gmail.com) 
     Commit Version: 1.6.0-4-g7f85cfe  Build Version: 1.6.7995.38578
     For more information, please see http://wiki.ros.org/sw_urdf_exporter -->
<robot
  name="Robot_irb1300_Pinza_Hsk">
  <link
    name="base_link">
    <inertial>
      <origin
        xyz="-0.022151 -0.00064381 0.12758"
        rpy="0 0 0" />
      <mass
        value="13.192" />
      <inertia
        ixx="0.11224"
        ixy="-0.00073677"
        ixz="-0.0030269"
        iyy="0.13529"
        iyz="0.0001119"
        izz="0.11132" />
    </inertial>
    <visual>
      <origin
        xyz="0 0 0"
        rpy="0 0 0" />
      <geometry>
        <mesh
          filename="package://Robot_irb1300_Pinza_Hsk/meshes/base_link.STL" />
      </geometry>
      <material
        name="">
        <color
          rgba="0.79216 0.81961 0.93333 1" />
      </material>
    </visual>
    <collision>
      <origin
        xyz="0 0 0"
        rpy="0 0 0" />
      <geometry>
        <mesh
          filename="package://Robot_irb1300_Pinza_Hsk/meshes/base_link.STL" />
      </geometry>
    </collision>
  </link>
  <link
    name="Link_1">
    <inertial>
      <origin
        xyz="-0.036497 -0.14933 -0.0023116"
        rpy="0 0 0" />
      <mass
        value="15.144" />
      <inertia
        ixx="0.18827"
        ixy="-0.019308"
        ixz="-0.0068491"
        iyy="0.13528"
        iyz="-0.044222"
        izz="0.16588" />
    </inertial>
    <visual>
      <origin
        xyz="0 0 0"
        rpy="0 0 0" />
      <geometry>
        <mesh
          filename="package://Robot_irb1300_Pinza_Hsk/meshes/Link_1.STL" />
      </geometry>
      <material
        name="">
        <color
          rgba="0.78039 0.8 0.78824 1" />
      </material>
    </visual>
    <collision>
      <origin
        xyz="0 0 0"
        rpy="0 0 0" />
      <geometry>
        <mesh
          filename="package://Robot_irb1300_Pinza_Hsk/meshes/Link_1.STL" />
      </geometry>
    </collision>
  </link>
  <joint
    name="Joint_0"
    type="revolute">
    <origin
      xyz="0.048394 -0.0033044 0.544"
      rpy="1.5708 0 -0.00131" />
    <parent
      link="base_link" />
    <child
      link="Link_1" />
    <axis
      xyz="0 1 0" />
    <limit
      lower="-3.14"
      upper="3.14"
      effort="0"
      velocity="4.88" />
  </joint>
  <link
    name="Link_2">
    <inertial>
      <origin
        xyz="-0.25758 0.0087787 1.2193E-06"
        rpy="0 0 0" />
      <mass
        value="13.168" />
      <inertia
        ixx="0.097006"
        ixy="-0.0027252"
        ixz="0.0043308"
        iyy="0.40092"
        iyz="3.6986E-05"
        izz="0.34742" />
    </inertial>
    <visual>
      <origin
        xyz="0 0 0"
        rpy="0 0 0" />
      <geometry>
        <mesh
          filename="package://Robot_irb1300_Pinza_Hsk/meshes/Link_2.STL" />
      </geometry>
      <material
        name="">
        <color
          rgba="0.78039 0.8 0.78824 1" />
      </material>
    </visual>
    <collision>
      <origin
        xyz="0 0 0"
        rpy="0 0 0" />
      <geometry>
        <mesh
          filename="package://Robot_irb1300_Pinza_Hsk/meshes/Link_2.STL" />
      </geometry>
    </collision>
  </link>
  <joint
    name="Joint_1"
    type="revolute">
    <origin
      xyz="-0.0033714 0.42497 -0.002246"
      rpy="0 0 1.5825" />
    <parent
      link="Link_1" />
    <child
      link="Link_2" />
    <axis
      xyz="0 0 1" />
    <limit
      lower="-1.74"
      upper="2.26"
      effort="0"
      velocity="3.97" />
  </joint>
  <link
    name="Link_3">
    <inertial>
      <origin
        xyz="-0.028609 0.0013664 0.005576"
        rpy="0 0 0" />
      <mass
        value="4.4211" />
      <inertia
        ixx="0.022585"
        ixy="0.00010962"
        ixz="-0.0015482"
        iyy="0.025924"
        iyz="-3.4884E-06"
        izz="0.014833" />
    </inertial>
    <visual>
      <origin
        xyz="0 0 0"
        rpy="0 0 0" />
      <geometry>
        <mesh
          filename="package://Robot_irb1300_Pinza_Hsk/meshes/Link_3.STL" />
      </geometry>
      <material
        name="">
        <color
          rgba="0.79216 0.81961 0.93333 1" />
      </material>
    </visual>
    <collision>
      <origin
        xyz="0 0 0"
        rpy="0 0 0" />
      <geometry>
        <mesh
          filename="package://Robot_irb1300_Pinza_Hsk/meshes/Link_3.STL" />
      </geometry>
    </collision>
  </link>
  <joint
    name="Joint_2"
    type="revolute">
    <origin
      xyz="0.039966 -0.0018091 -0.00099913"
      rpy="1.5708 0 -0.038982" />
    <parent
      link="Link_2" />
    <child
      link="Link_3" />
    <axis
      xyz="0 1 0" />
    <limit
      lower="-3.66"
      upper="1.13"
      effort="0"
      velocity="5.75" />
  </joint>
  <link
    name="Link_4">
    <inertial>
      <origin
        xyz="0.0012847 0.15674 0.0021747"
        rpy="0 0 0" />
      <mass
        value="3.6953" />
      <inertia
        ixx="0.029462"
        ixy="-0.00021694"
        ixz="6.9749E-05"
        iyy="0.0062115"
        iyz="0.0022669"
        izz="0.03077" />
    </inertial>
    <visual>
      <origin
        xyz="0 0 0"
        rpy="0 0 0" />
      <geometry>
        <mesh
          filename="package://Robot_irb1300_Pinza_Hsk/meshes/Link_4.STL" />
      </geometry>
      <material
        name="">
        <color
          rgba="0.79216 0.81961 0.93333 1" />
      </material>
    </visual>
    <collision>
      <origin
        xyz="0 0 0"
        rpy="0 0 0" />
      <geometry>
        <mesh
          filename="package://Robot_irb1300_Pinza_Hsk/meshes/Link_4.STL" />
      </geometry>
    </collision>
  </link>
  <joint
    name="Joint_3"
    type="revolute">
    <origin
      xyz="1.9864E-05 -0.00080502 0.42474"
      rpy="-1.5708 0 0.0027372" />
    <parent
      link="Link_3" />
    <child
      link="Link_4" />
    <axis
      xyz="0 1 0" />
    <limit
      lower="-4.01"
      upper="4.01"
      effort="0"
      velocity="8.72" />
  </joint>
  <link
    name="Link_5">
    <inertial>
      <origin
        xyz="5.8483E-05 -0.0089428 0.02235"
        rpy="0 0 0" />
      <mass
        value="0.60464" />
      <inertia
        ixx="0.0010433"
        ixy="-5.8934E-08"
        ixz="2.3034E-06"
        iyy="0.0010925"
        iyz="-0.00010986"
        izz="0.00052962" />
    </inertial>
    <visual>
      <origin
        xyz="0 0 0"
        rpy="0 0 0" />
      <geometry>
        <mesh
          filename="package://Robot_irb1300_Pinza_Hsk/meshes/Link_5.STL" />
      </geometry>
      <material
        name="">
        <color
          rgba="0.79216 0.81961 0.93333 1" />
      </material>
    </visual>
    <collision>
      <origin
        xyz="0 0 0"
        rpy="0 0 0" />
      <geometry>
        <mesh
          filename="package://Robot_irb1300_Pinza_Hsk/meshes/Link_5.STL" />
      </geometry>
    </collision>
  </link>
  <joint
    name="Joint_4"
    type="revolute">
    <origin
      xyz="-2.2787E-05 0 0.0011616"
      rpy="1.5708 0 0.0049617" />
    <parent
      link="Link_4" />
    <child
      link="Link_5" />
    <axis
      xyz="0 1 0" />
    <limit
      lower="-2.26"
      upper="2.26"
      effort="0"
      velocity="7.24" />
  </joint>
  <link
    name="Link_6">
    <inertial>
      <origin
        xyz="-0.0075113 8.3244E-05 -0.056129"
        rpy="0 0 0" />
      <mass
        value="0.18879" />
      <inertia
        ixx="0.00015292"
        ixy="-5.9238E-08"
        ixz="7.2743E-06"
        iyy="9.5682E-05"
        iyz="4.8014E-08"
        izz="0.00013292" />
    </inertial>
    <visual>
      <origin
        xyz="0 0 0"
        rpy="0 0 0" />
      <geometry>
        <mesh
          filename="package://Robot_irb1300_Pinza_Hsk/meshes/Link_6.STL" />
      </geometry>
      <material
        name="">
        <color
          rgba="0.79216 0.81961 0.93333 1" />
      </material>
    </visual>
    <collision>
      <origin
        xyz="0 0 0"
        rpy="0 0 0" />
      <geometry>
        <mesh
          filename="package://Robot_irb1300_Pinza_Hsk/meshes/Link_6.STL" />
      </geometry>
    </collision>
  </link>
  <joint
    name="Joint_5"
    type="revolute">
    <origin
      xyz="0.0035611 -0.00048331 0.17607"
      rpy="0 0 -0.040229" />
    <parent
      link="Link_5" />
    <child
      link="Link_6" />
    <axis
      xyz="0 0 1" />
    <limit
      lower="-6.98"
      upper="6.98"
      effort="0"
      velocity="12.56" />
  </joint>
</robot>