<?xml version="1.0" encoding="utf-8"?>
<!-- This URDF was automatically created by SolidWorks to URDF Exporter! Originally created by Stephen Brawner (brawner@gmail.com) 
     Commit Version: 1.6.0-4-g7f85cfe  Build Version: 1.6.7995.38578
     For more information, please see http://wiki.ros.org/sw_urdf_exporter -->
<robot
  name="URDF_FILES_irb1300.SLDASM">
  <link
    name="base_link">
    <inertial>
      <origin
        xyz="-0.022151 -0.00064382 0.12758"
        rpy="0 0 0" />
      <mass
        value="13.192" />
      <inertia
        ixx="0.11224"
        ixy="-0.00073678"
        ixz="-0.0030269"
        iyy="0.13529"
        iyz="0.00011189"
        izz="0.11132" />
    </inertial>
    <visual>
      <origin
        xyz="0 0 0"
        rpy="0 0 0" />
      <geometry>
        <mesh
          filename="package://URDF_FILES_irb1300.SLDASM/meshes/base_link.STL" />
      </geometry>
      <material
        name="">
        <color
          rgba="0.79216 0.81961 0.93333 1" />
      </material>
    </visual>
    <collision>
      <origin
        xyz="0 0 0"
        rpy="0 0 0" />
      <geometry>
        <mesh
          filename="package://URDF_FILES_irb1300.SLDASM/meshes/base_link.STL" />
      </geometry>
    </collision>
  </link>
  <link
    name="Link_1">
    <inertial>
      <origin
        xyz="-0.025728 -0.1462 -0.0010524"
        rpy="0 0 0" />
      <mass
        value="15.144" />
      <inertia
        ixx="0.18827"
        ixy="-0.019308"
        ixz="-0.0068481"
        iyy="0.13528"
        iyz="-0.044222"
        izz="0.16588" />
    </inertial>
    <visual>
      <origin
        xyz="0 0 0"
        rpy="0 0 0" />
      <geometry>
        <mesh
          filename="package://URDF_FILES_irb1300.SLDASM/meshes/Link_1.STL" />
      </geometry>
      <material
        name="">
        <color
          rgba="0.78039 0.8 0.78824 1" />
      </material>
    </visual>
    <collision>
      <origin
        xyz="0 0 0"
        rpy="0 0 0" />
      <geometry>
        <mesh
          filename="package://URDF_FILES_irb1300.SLDASM/meshes/Link_1.STL" />
      </geometry>
    </collision>
  </link>
  <joint
    name="joint_1"
    type="revolute">
    <origin
      xyz="0.037624 -0.0020669 0.54087"
      rpy="1.5708 0 -0.002284" />
    <parent
      link="base_link" />
    <child
      link="Link_1" />
    <axis
      xyz="0 1 0" />
    <limit
      lower="-3.14"
      upper="3.14"
      effort="0"
      velocity="4.88" />
  </joint>
  <link
    name="Link_2">
    <inertial>
      <origin
        xyz="-0.26005 0.010574 0.0016412"
        rpy="0 0 0" />
      <mass
        value="13.168" />
      <inertia
        ixx="0.097006"
        ixy="-0.0027252"
        ixz="0.0043308"
        iyy="0.40092"
        iyz="3.6986E-05"
        izz="0.34742" />
    </inertial>
    <visual>
      <origin
        xyz="0 0 0"
        rpy="0 0 0" />
      <geometry>
        <mesh
          filename="package://URDF_FILES_irb1300.SLDASM/meshes/Link_2.STL" />
      </geometry>
      <material
        name="">
        <color
          rgba="0.78039 0.8 0.78824 1" />
      </material>
    </visual>
    <collision>
      <origin
        xyz="0 0 0"
        rpy="0 0 0" />
      <geometry>
        <mesh
          filename="package://URDF_FILES_irb1300.SLDASM/meshes/Link_2.STL" />
      </geometry>
    </collision>
  </link>
  <joint
    name="joint_2"
    type="revolute">
    <origin
      xyz="0.012408 0.43061 -0.002626"
      rpy="0 0 1.5749" />
    <parent
      link="Link_1" />
    <child
      link="Link_2" />
    <axis
      xyz="0 0 1" />
    <limit
      lower="-1.74"
      upper="2.26"
      effort="0"
      velocity="3.97" />
  </joint>
  <link
    name="Link_3">
    <inertial>
      <origin
        xyz="-0.028049 0.0021765 0.005576"
        rpy="0 0 0" />
      <mass
        value="4.4211" />
      <inertia
        ixx="0.022585"
        ixy="0.00010962"
        ixz="-0.0015482"
        iyy="0.025924"
        iyz="-3.4899E-06"
        izz="0.014833" />
    </inertial>
    <visual>
      <origin
        xyz="0 0 0"
        rpy="0 0 0" />
      <geometry>
        <mesh
          filename="package://URDF_FILES_irb1300.SLDASM/meshes/Link_3.STL" />
      </geometry>
      <material
        name="">
        <color
          rgba="0.79216 0.81961 0.93333 1" />
      </material>
    </visual>
    <collision>
      <origin
        xyz="0 0 0"
        rpy="0 0 0" />
      <geometry>
        <mesh
          filename="package://URDF_FILES_irb1300.SLDASM/meshes/Link_3.STL" />
      </geometry>
    </collision>
  </link>
  <joint
    name="joint_3"
    type="revolute">
    <origin
      xyz="0.036972 0.0015817 -0.00016913"
      rpy="1.5708 0 0.0009373" />
    <parent
      link="Link_2" />
    <child
      link="Link_3" />
    <axis
      xyz="0 1 0" />
    <limit
      lower="-3.66"
      upper="1.13"
      effort="0"
      velocity="5.75" />
  </joint>
  <link
    name="Link_4">
    <inertial>
      <origin
        xyz="0.00082474 0.15587 0.0021747"
        rpy="0 0 0" />
      <mass
        value="3.6953" />
      <inertia
        ixx="0.029462"
        ixy="-0.00021694"
        ixz="6.9749E-05"
        iyy="0.0062115"
        iyz="0.0022669"
        izz="0.03077" />
    </inertial>
    <visual>
      <origin
        xyz="0 0 0"
        rpy="0 0 0" />
      <geometry>
        <mesh
          filename="package://URDF_FILES_irb1300.SLDASM/meshes/Link_4.STL" />
      </geometry>
      <material
        name="">
        <color
          rgba="0.79216 0.81961 0.93333 1" />
      </material>
    </visual>
    <collision>
      <origin
        xyz="0 0 0"
        rpy="0 0 0" />
      <geometry>
        <mesh
          filename="package://URDF_FILES_irb1300.SLDASM/meshes/Link_4.STL" />
      </geometry>
    </collision>
  </link>
  <joint
    name="joint_4"
    type="revolute">
    <origin
      xyz="0.0010333 0 0.42388"
      rpy="-1.5708 0 -0.0053999" />
    <parent
      link="Link_3" />
    <child
      link="Link_4" />
    <axis
      xyz="0 1 0" />
    <limit
      lower="-4.01"
      upper="4.01"
      effort="0"
      velocity="8.72" />
  </joint>
  <link
    name="Link_5">
    <inertial>
      <origin
        xyz="0.0016685 -0.0089428 0.022145"
        rpy="0 0 0" />
      <mass
        value="0.60464" />
      <inertia
        ixx="0.0010433"
        ixy="-5.897E-08"
        ixz="2.3033E-06"
        iyy="0.0010925"
        iyz="-0.00010986"
        izz="0.00052962" />
    </inertial>
    <visual>
      <origin
        xyz="0 0 0"
        rpy="0 0 0" />
      <geometry>
        <mesh
          filename="package://URDF_FILES_irb1300.SLDASM/meshes/Link_5.STL" />
      </geometry>
      <material
        name="">
        <color
          rgba="0.79216 0.81961 0.93333 1" />
      </material>
    </visual>
    <collision>
      <origin
        xyz="0 0 0"
        rpy="0 0 0" />
      <geometry>
        <mesh
          filename="package://URDF_FILES_irb1300.SLDASM/meshes/Link_5.STL" />
      </geometry>
    </collision>
  </link>
  <joint
    name="joint_5"
    type="revolute">
    <origin
      xyz="-0.0020946 -0.0010458 0.0011616"
      rpy="1.5708 0 -0.010128" />
    <parent
      link="Link_4" />
    <child
      link="Link_5" />
    <axis
      xyz="0 1 0" />
    <limit
      lower="-2.26"
      upper="2.26"
      effort="0"
      velocity="7.24" />
  </joint>
  <link
    name="Link_6">
    <inertial>
      <origin
        xyz="6.5663E-05 -8.8196E-05 -0.0047591"
        rpy="0 0 0" />
      <mass
        value="0.016904" />
      <inertia
        ixx="5.0668E-06"
        ixy="1.7611E-08"
        ixz="-8.0976E-10"
        iyy="5.2171E-06"
        iyz="3.3884E-10"
        izz="1.0089E-05" />
    </inertial>
    <visual>
      <origin
        xyz="0 0 0"
        rpy="0 0 0" />
      <geometry>
        <mesh
          filename="package://URDF_FILES_irb1300.SLDASM/meshes/Link_6.STL" />
      </geometry>
      <material
        name="">
        <color
          rgba="0.79216 0.81961 0.93333 1" />
      </material>
    </visual>
    <collision>
      <origin
        xyz="0 0 0"
        rpy="0 0 0" />
      <geometry>
        <mesh
          filename="package://URDF_FILES_irb1300.SLDASM/meshes/Link_6.STL" />
      </geometry>
    </collision>
  </link>
  <joint
    name="joint_6"
    type="revolute">
    <origin
      xyz="0.0015977 -0.00035506 0.092028"
      rpy="0 0 0.79443" />
    <parent
      link="Link_5" />
    <child
      link="Link_6" />
    <axis
      xyz="0 0 1" />
    <limit
      lower="-6.98"
      upper="6.98"
      effort="0"
      velocity="12.56" />
  </joint>
</robot>